<?xml version="1.0" encoding="utf-8"?><testsuites><testsuite name="pytest" errors="1" failures="0" skipped="0" tests="1" time="24.185" timestamp="2024-09-22T11:43:24.210333+05:30" hostname="PPH-LAP-01409"><testcase time="4.234" /><testcase classname="pytest" name="internal" time="0.000"><error message="internal error">Traceback (most recent call last):
  File "/home/saitejanannaka/.local/lib/python3.10/site-packages/_pytest/main.py", line 283, in wrap_session
    session.exitstatus = doit(config, session) or 0
  File "/home/saitejanannaka/.local/lib/python3.10/site-packages/_pytest/main.py", line 337, in _main
    config.hook.pytest_runtestloop(session=session)
  File "/home/saitejanannaka/.local/lib/python3.10/site-packages/pluggy/_hooks.py", line 513, in __call__
    return self._hookexec(self.name, self._hookimpls.copy(), kwargs, firstresult)
  File "/home/saitejanannaka/.local/lib/python3.10/site-packages/pluggy/_manager.py", line 120, in _hookexec
    return self._inner_hookexec(hook_name, methods, kwargs, firstresult)
  File "/home/saitejanannaka/.local/lib/python3.10/site-packages/pluggy/_callers.py", line 139, in _multicall
    raise exception.with_traceback(exception.__traceback__)
  File "/home/saitejanannaka/.local/lib/python3.10/site-packages/pluggy/_callers.py", line 122, in _multicall
    teardown.throw(exception)  # type: ignore[union-attr]
  File "/home/saitejanannaka/.local/lib/python3.10/site-packages/_pytest/logging.py", line 803, in pytest_runtestloop
    return (yield)  # Run all the tests.
  File "/home/saitejanannaka/.local/lib/python3.10/site-packages/pluggy/_callers.py", line 122, in _multicall
    teardown.throw(exception)  # type: ignore[union-attr]
  File "/home/saitejanannaka/.local/lib/python3.10/site-packages/_pytest/terminal.py", line 673, in pytest_runtestloop
    result = yield
  File "/home/saitejanannaka/.local/lib/python3.10/site-packages/pluggy/_callers.py", line 103, in _multicall
    res = hook_impl.function(*args)
  File "/home/saitejanannaka/.local/lib/python3.10/site-packages/_pytest/main.py", line 362, in pytest_runtestloop
    item.config.hook.pytest_runtest_protocol(item=item, nextitem=nextitem)
  File "/home/saitejanannaka/.local/lib/python3.10/site-packages/pluggy/_hooks.py", line 513, in __call__
    return self._hookexec(self.name, self._hookimpls.copy(), kwargs, firstresult)
  File "/home/saitejanannaka/.local/lib/python3.10/site-packages/pluggy/_manager.py", line 120, in _hookexec
    return self._inner_hookexec(hook_name, methods, kwargs, firstresult)
  File "/home/saitejanannaka/.local/lib/python3.10/site-packages/pluggy/_callers.py", line 139, in _multicall
    raise exception.with_traceback(exception.__traceback__)
  File "/home/saitejanannaka/.local/lib/python3.10/site-packages/pluggy/_callers.py", line 122, in _multicall
    teardown.throw(exception)  # type: ignore[union-attr]
  File "/home/saitejanannaka/.local/lib/python3.10/site-packages/_pytest/warnings.py", line 112, in pytest_runtest_protocol
    return (yield)
  File "/home/saitejanannaka/.local/lib/python3.10/site-packages/pluggy/_callers.py", line 122, in _multicall
    teardown.throw(exception)  # type: ignore[union-attr]
  File "/home/saitejanannaka/.local/lib/python3.10/site-packages/_pytest/assertion/__init__.py", line 176, in pytest_runtest_protocol
    return (yield)
  File "/home/saitejanannaka/.local/lib/python3.10/site-packages/pluggy/_callers.py", line 122, in _multicall
    teardown.throw(exception)  # type: ignore[union-attr]
  File "/home/saitejanannaka/.local/lib/python3.10/site-packages/_pytest/unittest.py", line 429, in pytest_runtest_protocol
    res = yield
  File "/home/saitejanannaka/.local/lib/python3.10/site-packages/pluggy/_callers.py", line 122, in _multicall
    teardown.throw(exception)  # type: ignore[union-attr]
  File "/home/saitejanannaka/.local/lib/python3.10/site-packages/_pytest/faulthandler.py", line 88, in pytest_runtest_protocol
    return (yield)
  File "/home/saitejanannaka/.local/lib/python3.10/site-packages/pluggy/_callers.py", line 103, in _multicall
    res = hook_impl.function(*args)
  File "/home/saitejanannaka/.local/lib/python3.10/site-packages/_pytest/runner.py", line 113, in pytest_runtest_protocol
    runtestprotocol(item, nextitem=nextitem)
  File "/home/saitejanannaka/.local/lib/python3.10/site-packages/_pytest/runner.py", line 132, in runtestprotocol
    reports.append(call_and_report(item, "call", log))
  File "/home/saitejanannaka/.local/lib/python3.10/site-packages/_pytest/runner.py", line 244, in call_and_report
    report: TestReport = ihook.pytest_runtest_makereport(item=item, call=call)
  File "/home/saitejanannaka/.local/lib/python3.10/site-packages/pluggy/_hooks.py", line 513, in __call__
    return self._hookexec(self.name, self._hookimpls.copy(), kwargs, firstresult)
  File "/home/saitejanannaka/.local/lib/python3.10/site-packages/pluggy/_manager.py", line 120, in _hookexec
    return self._inner_hookexec(hook_name, methods, kwargs, firstresult)
  File "/home/saitejanannaka/.local/lib/python3.10/site-packages/pluggy/_callers.py", line 156, in _multicall
    teardown[0].send(outcome)
  File "/home/saitejanannaka/Automation/TejaProjects/centime_automation/conftest.py", line 22, in pytest_runtest_makereport
    driver.save_screenshot(screenshot_path)
  File "/home/saitejanannaka/.local/lib/python3.10/site-packages/selenium/webdriver/remote/webdriver.py", line 952, in save_screenshot
    return self.get_screenshot_as_file(filename)
  File "/home/saitejanannaka/.local/lib/python3.10/site-packages/selenium/webdriver/remote/webdriver.py", line 927, in get_screenshot_as_file
    png = self.get_screenshot_as_png()
  File "/home/saitejanannaka/.local/lib/python3.10/site-packages/selenium/webdriver/remote/webdriver.py", line 963, in get_screenshot_as_png
    return b64decode(self.get_screenshot_as_base64().encode('ascii'))
  File "/home/saitejanannaka/.local/lib/python3.10/site-packages/selenium/webdriver/remote/webdriver.py", line 975, in get_screenshot_as_base64
    return self.execute(Command.SCREENSHOT)['value']
  File "/home/saitejanannaka/.local/lib/python3.10/site-packages/selenium/webdriver/remote/webdriver.py", line 429, in execute
    self.error_handler.check_response(response)
  File "/home/saitejanannaka/.local/lib/python3.10/site-packages/selenium/webdriver/remote/errorhandler.py", line 243, in check_response
    raise exception_class(message, screen, stacktrace)
selenium.common.exceptions.NoSuchWindowException: Message: no such window: target window already closed
from unknown error: web view not found
  (Session info: chrome=129.0.6668.58)
Stacktrace:
#0 0x560da3f3713a &lt;unknown&gt;
#1 0x560da3c1d5e0 &lt;unknown&gt;
#2 0x560da3bf31af &lt;unknown&gt;
#3 0x560da3c9a03d &lt;unknown&gt;
#4 0x560da3cb0629 &lt;unknown&gt;
#5 0x560da3c918c3 &lt;unknown&gt;
#6 0x560da3c5f6b3 &lt;unknown&gt;
#7 0x560da3c6068e &lt;unknown&gt;
#8 0x560da3f01b3b &lt;unknown&gt;
#9 0x560da3f05ac1 &lt;unknown&gt;
#10 0x560da3eee335 &lt;unknown&gt;
#11 0x560da3f06642 &lt;unknown&gt;
#12 0x560da3ed349f &lt;unknown&gt;
#13 0x560da3f26038 &lt;unknown&gt;
#14 0x560da3f26203 &lt;unknown&gt;
#15 0x560da3f35f8c &lt;unknown&gt;
#16 0x7e9484e94ac3 &lt;unknown&gt;</error></testcase></testsuite></testsuites>